Workbook

Sheet BoP SUMMARY
B2: Willio & Dave CH - Consolidato 5 Yrs. 5 Locations
C4: PERFORMANCE INDICATORS | E4: total | F4: PERFORMANCE ON REVENUE
C5: Total Area | D5: sqm | E5: =+'SITE Model - INPUT PARAMETERS'!D3 -> 400
C7: Total Personnel | D7: # | E7: (16 x 5) 80
C9: Total Investments | E9: ='SITE Model - INPUT PARAMETERS'!C35 -> 430000
C10: =+'SITE Model - INPUT PARAMETERS'!B36 -> licencee acquisition | E10: =+'SITE Model - INPUT PARAMETERS'!C36 -> 50000
C11: =+'SITE Model - INPUT PARAMETERS'!B37 -> restructuring & revamping | E11: =+'SITE Model - INPUT PARAMETERS'!C37 -> 250000
C13: Financial plan
C15: Loan from Investors | E15: =+'SITE Model - INPUT PARAMETERS'!C40 -> 430000
E16: =+'SITE Model - INPUT PARAMETERS'!C38
C17: Banking loan | E17: =+'SITE Model - INPUT PARAMETERS'!C43 -> 50000
C19: Program financial index*
C20: IRR - First 10 Years | D20: % | E20: ='CF SITES'!F68 -> 1.0643159
C21: PI - Profitability Index - First 10 Years | D21: # | E21: ='CF SITES'!F72 -> 12.509183
C22: NPV - First 10 Years | D22: CHF | E22: ='CF SITES'!F71*1000 -> 4948948.6
C23: AVG. REVENUE per YEAR - Avg. 10 Years | D23: CHF | E23: =SUM('SITES Conld. P&L'!D39:M39)/10 -> 8175914
C24: AVG. OPERATING COSTS per YEAR - Avg. 10 Years | D24: CHF | E24: =SUM('SITES Conld. P&L'!D51:M51)/10 -> 6730465.1 | F24: =+E24/$E$23 -> 0.82320645
C25: AVG. EBITDA per YEAR - Avg. 10 Years | D25: CHF | E25: =SUM('SITES Conld. P&L'!D53:M53)/10 -> 1445448.9 | F25: =+E25/$E$23 -> 0.17679355
C26: AVG. EBIT per YEAR - Avg. 10 Years | D26: CHF | E26: =SUM('SITES Conld. P&L'!D55:M55)/10 -> 1402448.9 | F26: =+E26/$E$23 -> 0.1715342
C27: AVG. NET INCOME per YEAR - Avg. 10 Years | D27: CHF | E27: =SUM('SITES Conld. P&L'!D$60:M$60)/10 -> 971944.23 | F27: =+E27/$E$23 -> 0.11887897
C28: AVG. NET INCOME per YEAR - Avg. Years 1-3 | D28: CHF | E28: =SUM('SITES Conld. P&L'!D$60:F$60)/3 -> 493734.69
C29: AVG. NET INCOME per YEAR - Avg. Years 1-5 | D29: CHF | E29: =SUM('SITES Conld. P&L'!D$60:H$60)/5 -> 705461.28
C30: AVG. NET INCOME per YEAR - Avg. Years 6-10 | D30: CHF | E30: =SUM('SITES Conld. P&L'!I$60:M$60)/5 -> 1238427.2
C32: *Note: tax credit compensation has not be included

Sheet CF SITES
A1: 1000 | F1: Willio & David
A2: Cash flow statement (thousand CHFs). | E2: U | N2: 9 | O2: 10 | P2: 11 | Q2: 12 | R2: 13 | S2: 14 | T2: 15 | U2: 16 | V2: 17 | W2: 18 | X2: 19 | Y2: 20 | Z2: 21 | AA2: 22 | AB2: 23 | AC2: 24 | AD2: 25
B4: Cash flows from operating activities | E4: thousand CHF | F4: =SUM(F5:F9)+F20 -> 343.219 | G4: =SUM(G5:G9)+G20 -> 539.69593 | H4: =SUM(H5:H9)+H20 -> 727.28912 | I4: =SUM(I5:I9)+I20 -> 889.45805 | J4: =SUM(J5:J9)+J20 -> 1242.6443 | K4: =SUM(K5:K9)+K20 -> 1256.2665 | L4: =SUM(L5:L9)+L20 -> 1268.7217 | M4: =SUM(M5:M9)+M20 -> 1281.3014 | ... AD4: =SUM(AD5:AD9)+AD20 -> 1504.7196
C5: Business receipts | E5: thousand CHF | F5: =+'SITES Conld. P&L'!D39/$A$1 -> 2095.2 | G5: =+'SITES Conld. P&L'!E39/$A$1 -> 4024.872 | H5: =+'SITES Conld. P&L'!F39/$A$1 -> 5958.6247 | I5: =+'SITES Conld. P&L'!G39/$A$1 -> 7867.3447 | J5: =+'SITES Conld. P&L'!H39/$A$1 -> 10047.618 | K5: =+'SITES Conld. P&L'!I39/$A$1 -> 10148.094 | L5: =+'SITES Conld. P&L'!J39/$A$1 -> 10249.575 | M5: =+'SITES Conld. P&L'!K39/$A$1 -> 10352.071 | ... AD5: =+'SITES Conld. P&L'!AB39/$A$1 -> 12260.004 | AE5: =SUM(F5:AD5) -> 253444.59
C6: CGS | E6: thousand CHF | F6: =-'SITES Conld. P&L'!D50/$A$1 -> -672.848 | G6: =-'SITES Conld. P&L'!E50/$A$1 -> -1359.153 | H6: =-'SITES Conld. P&L'!F50/$A$1 -> -2045.5925 | I6: =-'SITES Conld. P&L'!G50/$A$1 -> -2738.8964 | J6: =-'SITES Conld. P&L'!H50/$A$1 -> -3439.1334 | K6: =-'SITES Conld. P&L'!I50/$A$1 -> -3473.5247 | L6: =-'SITES Conld. P&L'!J50/$A$1 -> -3508.26 | M6: =-'SITES Conld. P&L'!K50/$A$1 -> -3543.3426 | ... AD6: =-'SITES Conld. P&L'!AB50/$A$1 -> -4196.3963 | AE6: =SUM(F6:AD6) -> -86739.178
C7: Labor costs | E7: thousand CHF | F7: =-'SITES Conld. P&L'!D43/$A$1 -> -946 | G7: =-'SITES Conld. P&L'!E43/$A$1 -> -1910.92 | H7: =-'SITES Conld. P&L'!F43/$A$1 -> -2876.0292 | I7: =-'SITES Conld. P&L'!G43/$A$1 -> -3850.7895 | J7: =-'SITES Conld. P&L'!H43/$A$1 -> -4835.2974 | K7: =-'SITES Conld. P&L'!I43/$A$1 -> -4883.6504 | L7: =-'SITES Conld. P&L'!J43/$A$1 -> -4932.4869 | M7: =-'SITES Conld. P&L'!K43/$A$1 -> -4981.8117 | ... AD7: =-'SITES Conld. P&L'!AB43/$A$1 -> -5899.9817 | AE7: =SUM(F7:AD7) -> -121952.15
C8: O/H Expenses | E8: thousand CHF | F8: 0 | G8: 0 | H8: 0 | I8: 0 | J8: 0 | K8: 0 | L8: 0 | M8: 0 | N8: 0 | O8: 0 | P8: 0 | Q8: 0 | R8: 0 | S8: 0 | T8: 0 | U8: 0 | V8: 0 | W8: 0 | X8: 0 | Y8: 0 | Z8: 0 | AA8: 0 | AB8: 0 | AC8: 0 | AD8: 0
C9: taxes | E9: thousand CHF | F9: =-(F17+F18+F19+IF('CF SITES'!F16>0, 'CF SITES'!F16, 0)) -> -109.633 | G9: =-(G17+G18+G19+IF('CF SITES'!G16>0, 'CF SITES'!G16, 0)) -> -195.86332 | H9: =-(H17+H18+H19+IF('CF SITES'!H16>0, 'CF SITES'!H16, 0)) -> -294.94365 | I9: =-(I17+I18+I19+IF('CF SITES'!I16>0, 'CF SITES'!I16, 0)) -> -378.11968 | J9: =-(J17+J18+J19+IF('CF SITES'!J16>0, 'CF SITES'!J16, 0)) -> -525.38172 | K9: =-(K17+K18+K19+IF('CF SITES'!K16>0, 'CF SITES'!K16, 0)) -> -534.65284 | L9: =-(L17+L18+L19+IF('CF SITES'!L16>0, 'CF SITES'!L16, 0)) -> -540.10687 | M9: =-(M17+M18+M19+IF('CF SITES'!M16>0, 'CF SITES'!M16, 0)) -> -545.61544 | ... AD9: =-(AD17+AD18+AD19+IF('CF SITES'!AD16>0, 'CF SITES'!AD16, 0)) -> -658.90606
D10: VAT received | F10: 0 | G10: 0 | H10: 0 | I10: 0 | J10: 0 | K10: 0 | L10: 0 | M10: 0 | N10: 0 | O10: 0 | P10: 0 | Q10: 0 | R10: 0 | S10: 0 | T10: 0 | U10: 0 | V10: 0 | W10: 0 | X10: 0 | Y10: 0 | Z10: 0 | AA10: 0 | AB10: 0 | AC10: 0 | AD10: 0
D11: VAT paid | F11: 0 | G11: 0 | H11: 0 | I11: 0 | J11: 0 | K11: 0 | L11: 0 | M11: 0 | N11: 0 | O11: 0 | P11: 0 | Q11: 0 | R11: 0 | S11: 0 | T11: 0 | U11: 0 | V11: 0 | W11: 0 | X11: 0 | Y11: 0 | Z11: 0 | AA11: 0 | AB11: 0 | AC11: 0 | AD11: 0
D12: VAT receivable - VAT paid | F12: 0 | G12: 0 | H12: 0 | I12: 0 | J12: 0 | K12: 0 | L12: 0 | M12: 0 | N12: 0 | O12: 0 | P12: 0 | Q12: 0 | R12: 0 | S12: 0 | T12: 0 | U12: 0 | V12: 0 | W12: 0 | X12: 0 | Y12: 0 | Z12: 0 | AA12: 0 | AB12: 0 | AC12: 0 | AD12: 0
D13: The amount of VAT receivable - VAT paid | F13: 0 | G13: 0 | H13: 0 | I13: 0 | J13: 0 | K13: 0 | L13: 0 | M13: 0 | N13: 0 | O13: 0 | P13: 0 | Q13: 0 | R13: 0 | S13: 0 | T13: 0 | U13: 0 | V13: 0 | W13: 0 | X13: 0 | Y13: 0 | Z13: 0 | AA13: 0 | AB13: 0 | AC13: 0 | AD13: 0
D14: auxiliary strokk | F14: 0 | G14: 0 | H14: 0 | I14: 0 | J14: 0 | K14: 0 | L14: 0 | M14: 0 | N14: 0 | O14: 0 | P14: 0 | Q14: 0 | R14: 0 | S14: 0 | T14: 0 | U14: 0 | V14: 0 | W14: 0 | X14: 0 | Y14: 0 | Z14: 0 | AA14: 0 | AB14: 0 | AC14: 0 | AD14: 0
D15: auxiliary strokk | F15: 0 | G15: 0 | H15: 0 | I15: 0 | J15: 0 | K15: 0 | L15: 0 | M15: 0 | N15: 0 | O15: 0 | P15: 0 | Q15: 0 | R15: 0 | S15: 0 | T15: 0 | U15: 0 | V15: 0 | W15: 0 | X15: 0 | Y15: 0 | Z15: 0 | AA15: 0 | AB15: 0 | AC15: 0 | AD15: 0
D16: VAT to be paid to (+) / repayment (-) | F16: 0 | G16: 0 | H16: 0 | I16: 0 | J16: 0 | K16: 0 | L16: 0 | M16: 0 | N16: 0 | O16: 0 | P16: 0 | Q16: 0 | R16: 0 | S16: 0 | T16: 0 | U16: 0 | V16: 0 | W16: 0 | X16: 0 | Y16: 0 | Z16: 0 | AA16: 0 | AB16: 0 | AC16: 0 | AD16: 0
D17: Insurance premiums in the gov't. extrabudgetary funds | F17: 0 | G17: 0 | H17: 0 | I17: 0 | J17: 0 | K17: 0 | L17: 0 | M17: 0 | N17: 0 | O17: 0 | P17: 0 | Q17: 0 | R17: 0 | S17: 0 | T17: 0 | U17: 0 | V17: 0 | W17: 0 | X17: 0 | Y17: 0 | Z17: 0 | AA17: 0 | AB17: 0 | AC17: 0 | AD17: 0
D18: Property tax | F18: 0 | G18: 0 | H18: 0 | I18: 0 | J18: 0 | K18: 0 | L18: 0 | M18: 0 | N18: 0 | O18: 0 | P18: 0 | Q18: 0 | R18: 0 | S18: 0 | T18: 0 | U18: 0 | V18: 0 | W18: 0 | X18: 0 | Y18: 0 | Z18: 0 | AA18: 0 | AB18: 0 | AC18: 0 | AD18: 0
D19: Corporate taxes | F19: ='SITES Conld. P&L'!D91/$A$1 -> 109.633 | G19: ='SITES Conld. P&L'!E91/$A$1 -> 195.86332 | H19: ='SITES Conld. P&L'!F91/$A$1 -> 294.94365 | I19: ='SITES Conld. P&L'!G91/$A$1 -> 378.11968 | J19: ='SITES Conld. P&L'!H91/$A$1 -> 525.38172 | K19: ='SITES Conld. P&L'!I91/$A$1 -> 534.65284 | L19: ='SITES Conld. P&L'!J91/$A$1 -> 540.10687 | M19: ='SITES Conld. P&L'!K91/$A$1 -> 545.61544 | ... AD19: ='SITES Conld. P&L'!AB91/$A$1 -> 658.90606 | AE19: =SUM(F19:AD19) -> 13354.419
C20: Payment of interest on loans | E20: thousand CHF | F20: ='SITES Conld. P&L'!D56/$A$1 -> -23.5 | G20: ='SITES Conld. P&L'!E56/$A$1 -> -19.239788 | H20: ='SITES Conld. P&L'!F56/$A$1 -> -14.770257 | I20: ='SITES Conld. P&L'!G56/$A$1 -> -10.08109 | J20: ='SITES Conld. P&L'!H56/$A$1 -> -5.1614592 | K20: ='SITES Conld. P&L'!I56/$A$1 -> 0 | L20: ='SITES Conld. P&L'!J56/$A$1 -> 0 | M20: ='SITES Conld. P&L'!K56/$A$1 -> 0 | ... AD20: ='SITES Conld. P&L'!AB56/$A$1 -> 0 | AE20: =SUM(F20:AD20) -> -72.752594
B22: Cash flows from investing activities | E22: thousand CHF | F22: =F23+F24 -> -430 | G22: =G23+G24 -> 0 | H22: =H23+H24 -> 0 | I22: =I23+I24 -> 0 | J22: =J23+J24 -> 0 | K22: =K23+K24 -> 0 | L22: =L23+L24 -> 0 | M22: =M23+M24 -> 0 | ... AD22: =AD23+AD24 -> 0
C23: Investments in fixed assets | E23: thousand CHF | F23: =+'SITES Conld. P&L'!D65/A1 -> -430
C24: Investments in working capital | E24: thousand CHF
B26: Cash flows from financing activities | E26: thousand CHF | F26: =SUM(F27:F33) -> 392.94948 | G26: =SUM(G27:G33) -> -91.310731 | H26: =SUM(H27:H33) -> -95.780262 | I26: =SUM(I27:I33) -> -100.46943 | J26: =SUM(J27:J33) -> -105.38906 | K26: =SUM(K27:K33) -> 0 | L26: =SUM(L27:L33) -> 0 | M26: =SUM(M27:M33) -> 0 | ... AD26: =SUM(AD27:AD33) -> 0
E27: thousand CHF | F27: =+'SITES Conld. P&L'!D69/A1 -> 0 | G27: 0 | H27: 0 | I27: 0 | J27: 0 | K27: 0 | L27: 0 | M27: 0 | N27: 0 | O27: 0 | P27: 0 | Q27: 0 | R27: 0 | S27: 0 | T27: 0 | U27: 0 | V27: 0 | W27: 0 | X27: 0 | Y27: 0 | Z27: 0 | AA27: 0 | AB27: 0 | AC27: 0 | AD27: 0 | AE27: =SUM(F27:AD27) -> 0
C28: Investors loan put in equity | E28: thousand CHF | F28: =+'SITES Conld. P&L'!D72/A1 -> 430 | G28: =+'SITES Conld. P&L'!E69/$A$1 -> 0 | H28: =+'SITES Conld. P&L'!F69/$A$1 -> 0 | I28: =+'SITES Conld. P&L'!G69/$A$1 -> 0 | J28: =+'SITES Conld. P&L'!H69/$A$1 -> 0 | K28: =+'SITES Conld. P&L'!I69/$A$1 -> 0 | L28: =+'SITES Conld. P&L'!J69/$A$1 -> 0 | M28: =+'SITES Conld. P&L'!K69/$A$1 -> 0 | N28: =+'SITES Conld. P&L'!L69/$A$1 -> 0 | ... AD28: =+'SITES Conld. P&L'!AB69/$A$1 -> 0 | AE28: =SUM(F28:AD28) -> 430
C29: Grants | E29: thousand CHF | F29: =+'SITES Conld. P&L'!D70/A1 -> 0 | G29: =+'SITES Conld. P&L'!E70/$A$1 -> 0 | H29: =+'SITES Conld. P&L'!F70/$A$1 -> 0 | I29: =+'SITES Conld. P&L'!G70/$A$1 -> 0 | J29: =+'SITES Conld. P&L'!H70/$A$1 -> 0 | K29: =+'SITES Conld. P&L'!I70/$A$1 -> 0 | L29: =+'SITES Conld. P&L'!J70/$A$1 -> 0 | M29: =+'SITES Conld. P&L'!K70/$A$1 -> 0 | N29: =+'SITES Conld. P&L'!L70/$A$1 -> 0 | ... AD29: =+'SITES Conld. P&L'!AB70/$A$1 -> 0 | AE29: =SUM(F29:AD29) -> 0
C30: Investors financing repayment | E30: thousand CHF | F30: =+'SITES Conld. P&L'!D71/$A$1 -> -77.819163 | G30: =+'SITES Conld. P&L'!E71/$A$1 -> -81.710121 | H30: =+'SITES Conld. P&L'!F71/$A$1 -> -85.795627 | I30: =+'SITES Conld. P&L'!G71/$A$1 -> -90.085409 | J30: =+'SITES Conld. P&L'!H71/$A$1 -> -94.589679 | K30: =+'SITES Conld. P&L'!I71/$A$1 -> 0 | L30: =+'SITES Conld. P&L'!J71/$A$1 -> 0 | M30: =+'SITES Conld. P&L'!K71/$A$1 -> 0 | ... AD30: =+'SITES Conld. P&L'!AB71/$A$1 -> 0 | AE30: =SUM(F30:AD30) -> -430
C31: Banking loan | E31: thousand CHF | F31: =+'SITES Conld. P&L'!D67/A1 -> 50 | G31: 0 | H31: 0 | I31: 0 | J31: 0 | K31: 0 | L31: 0 | M31: 0 | N31: 0 | O31: 0 | P31: 0 | Q31: 0 | R31: 0 | S31: 0 | T31: 0 | U31: 0 | V31: 0 | W31: 0 | X31: 0 | Y31: 0 | Z31: 0 | AA31: 0 | AB31: 0 | AC31: 0 | AD31: 0 | AE31: =SUM(F31:AD31) -> 50
C32: banking loan repayment | E32: thousand CHF | F32: =+'SITES Conld. P&L'!D68/$A$1 -> -9.2313557 | G32: =+'SITES Conld. P&L'!E68/$A$1 -> -9.6006099 | H32: =+'SITES Conld. P&L'!F68/$A$1 -> -9.9846343 | I32: =+'SITES Conld. P&L'!G68/$A$1 -> -10.38402 | J32: =+'SITES Conld. P&L'!H68/$A$1 -> -10.79938 | K32: =+'SITES Conld. P&L'!I68/$A$1 -> 0 | L32: =+'SITES Conld. P&L'!J68/$A$1 -> 0 | M32: =+'SITES Conld. P&L'!K68/$A$1 -> 0 | ... AD32: =+'SITES Conld. P&L'!AB68/$A$1 -> 0 | AE32: =SUM(F32:AD32) -> -50
C33: Dividend payment | E33: thousand CHF | F33: 0 | G33: 0 | H33: 0 | I33: 0 | J33: 0 | K33: 0 | L33: 0 | M33: 0 | N33: 0 | O33: 0 | P33: 0 | Q33: 0 | R33: 0 | S33: 0 | T33: 0 | U33: 0 | V33: 0 | W33: 0 | X33: 0 | Y33: 0 | Z33: 0 | AA33: 0 | AB33: 0 | AC33: 0 | AD33: 0 | AE33: =SUM(F33:AD33) -> 0
B35: Total cash flow for the period | E35: thousand CHF | F35: =F4+F22+F26 -> 306.16848 | G35: =G4+G22+G26 -> 448.3852 | H35: =H4+H22+H26 -> 631.50886 | I35: =I4+I22+I26 -> 788.98862 | J35: =J4+J22+J26 -> 1137.2552 | K35: =K4+K22+K26 -> 1256.2665 | L35: =L4+L22+L26 -> 1268.7217 | M35: =M4+M22+M26 -> 1281.3014 | ... AD35: =AD4+AD22+AD26 -> 1504.7196
B36: Cash eop | E36: thousand CHF | F36: =SUM($F35:F35) -> 306.16848 | G36: =SUM($F35:G35) -> 754.55368 | H36: =SUM($F35:H35) -> 1386.0625 | I36: =SUM($F35:I35) -> 2175.0512 | J36: =SUM($F35:J35) -> 3312.3064 | K36: =SUM($F35:K35) -> 4568.5729 | L36: =SUM($F35:L35) -> 5837.2946 | M36: =SUM($F35:M35) -> 7118.596 | ... AD36: =SUM($F35:AD35) -> 30896.089
F37: =+'SITES Conld. P&L'!D74/$A$1-F36 -> 0 | G37: =+'SITES Conld. P&L'!E74/$A$1-G36 -> 0 | H37: =+'SITES Conld. P&L'!F74/$A$1-H36 -> 0 | I37: =+'SITES Conld. P&L'!G74/$A$1-I36 -> 0 | J37: =+'SITES Conld. P&L'!H74/$A$1-J36 -> 0 | K37: =+'SITES Conld. P&L'!I74/$A$1-K36 -> 0 | L37: =+'SITES Conld. P&L'!J74/$A$1-L36 -> 0 | M37: =+'SITES Conld. P&L'!K74/$A$1-M36 -> 0 | ... AD37: =+'SITES Conld. P&L'!AB74/$A$1-AD36 -> 0
B40: Key Performance Indicators
C41: Cash flow (FCF) | E41: thousand CHF | F41: =+F35 -> 306.16848 | G41: =+G35 -> 448.3852 | H41: =+H35 -> 631.50886 | I41: =+I35 -> 788.98862 | J41: =+J35 -> 1137.2552 | K41: =+K35 -> 1256.2665 | L41: =+L35 -> 1268.7217 | M41: =+M35 -> 1281.3014 | ... AD41: =+AD35 -> 1504.7196
C42: Cash flow on an accrual basis | E42: thousand CHF | F42: =+F36 -> 306.16848 | G42: =+G36 -> 754.55368 | H42: =+H36 -> 1386.0625 | I42: =+I36 -> 2175.0512 | J42: =+J36 -> 3312.3064 | K42: =+K36 -> 4568.5729 | L42: =+L36 -> 5837.2946 | M42: =+M36 -> 7118.596 | ... AD42: =+AD36 -> 30896.089
C43: The average growth rate FCF | F43: 0 | G43: =IF(G41=0,"-",(G41-F41)/G41) -> 0.31717532 | H43: =IF(H41=0,"-",(H41-G41)/H41) -> 0.28997797 | I43: =IF(I41=0,"-",(I41-H41)/I41) -> 0.19959699 | J43: =IF(J41=0,"-",(J41-I41)/J41) -> 0.30623435 | K43: =IF(K41=0,"-",(K41-J41)/K41) -> 0.094734095 | L43: =IF(L41=0,"-",(L41-K41)/L41) -> 0.0098170981 | M43: =IF(M41=0,"-",(M41-L41)/M41) -> 0.0098179217 | N43: =IF(N41=0,"-",(N41-M41)/N41) -> 0.0098187373 | ... AD43: =IF(AD41=0,"-",(AD41-AC41)/AD41) -> 0.0099009901
C45: Discount coefficient | F45: =1/(1+$F$54)^F2 -> 1 | G45: =1/(1+$F$54)^G2 -> 1 | H45: =1/(1+$F$54)^H2 -> 1 | I45: =1/(1+$F$54)^I2 -> 1 | J45: =1/(1+$F$54)^J2 -> 1 | K45: =1/(1+$F$54)^K2 -> 1 | L45: =1/(1+$F$54)^L2 -> 1 | M45: =1/(1+$F$54)^M2 -> 1 | ... AD45: =1/(1+$F$54)^AD2 -> 0.092295998
C46: discount function
C47: Discounted Cash Flow | E47: thousand CHF | F47: =+F41*F45 -> 306.16848 | G47: =+G41*G45 -> 448.3852 | H47: =+H41*H45 -> 631.50886 | I47: =+I41*I45 -> 788.98862 | J47: =+J41*J45 -> 1137.2552 | K47: =+K41*K45 -> 1256.2665 | L47: =+L41*L45 -> 1268.7217 | M47: =+M41*M45 -> 1281.3014 | ... AD47: =+AD41*AD45 -> 138.8796
...

Sheet SITE Model - INPUT PARAMETERS
B2: Site Geneva (renting formula) | F2: CAPEX ReVamping Piattaforma
B3: total area (including openair area) | D3: =C4 -> 400 | F3: total capex Revamping | H3: =SUM(H4:H11) -> 250000
B4: Location | C4: =C6+C8 -> 400 | D4: =D6+D8+D10 -> 230000 | F4: Kitchen | H4: 100000
B5: posti a sedere | C5: 120 | F5: Restaurant (inside) | H5: 50000
B6: affitto 1 | C6: 250 | D6: 120000 | F6: Restaurant (and open air) | H6: 25000
B7: posti a sedere | C7: 80 | F7: Bar | H7: 5000
B8: affitto 2 | C8: 150 | D8: 60000 | F8: Wine cellar | H8: 5000
B9: posti a sedere | C9: 40 | F9: Technical area | H9: 10000
B10: Scouting. Consultants . Profesional . Legal. Licence | D10: 50000 | F10: Office + web Cam + Security ect | H10: 30000
B11: Total Capex Platfrom Geneva | D11: =D4 -> 230000 | F11: stigliature | H11: 25000
B13: recurring costs for raw material | F13: Opex General expences | J13: Personnel costs
B14: * calculated on the relevant revenues | F14: * calculated on the total yearly income
B15: raw material for food* | C15: 0.1 | D15: ='SITES Conld. P&L'!D45 -> 170808 | F15: operating expences* | J15: total personnel costs | K15: 0.3
B16: raw material for beverage* | C16: 0.15 | D16: ='SITES Conld. P&L'!D46 -> 32040 | F16: Administration * | G16: =10000*12 -> 120000 | J16: Place A ( 8 Units) RAL Media Unit | K16: =5500*8 -> 44000 | L16: =K16*8 -> 352000
F17: Utilities | G17: =10000*12 -> 120000 | J17: Place B (4 Units) | K17: =5500*12 -> 66000 | L17: =K17*5 -> 330000
F18: Rent 1 | G18: 120000 | J18: Adm. Trasp.Logistics (4 Units) | K18: =5500*12 -> 66000 | L18: =K18*4 -> 264000
F19: rent 2 | G19: 60000
F20: Contigencies | G20: 50000
D21: =D15+D16 -> 202848 | H21: =SUM(G16:G20) -> 470000 | L21: =SUM(L16:L20) -> 946000
B27: INVESTMENT PARAMETERS
B29: Yearly inflation rate | C29: 0.01
B30: Discount rate | C30: 0.1
B34: TOTAL INVESTMENT SUMMARY
B35: Amount of total investment | C35: =D6+D8+H3 -> 430000 | D35: CHF
B36: licencee acquisition | C36: =D10 -> 50000 | D36: CHF
B37: restructuring & revamping | C37: =+H3 -> 250000 | D37: CHF
B40: loan from investors | C40: =C35 -> 430000 | D40: CHF
B41: interest rate | C41: 0.05 | D41: %
B42: Duration of loan | C42: 5 | D42: years
B43: banking credit line | C43: 50000 | D43: CHF
B44: average interest rate | C44: 0.04 | D44: %
B45: Duration of credit | C45: 5 | D45: years

Sheet SITES Conld. P&L
B1: 3 | C1: Willio & David
B2: Industrial production for Ready Plate , souces & sandwiches - Montalbano, Fumetti, Monteriggioni
B9: SENIOR DEBT TABLE
B13: Investors' loan | D13: 1 | E13: 2 | F13: 3 | G13: 4 | H13: 5 | I13: 6 | J13: 7 | K13: 8 | L13: 9 | M13: 10 | N13: 11 | O13: 12 | P13: 13 | Q13: 14 | R13: 15 | S13: 16 | T13: 17 | U13: 18 | V13: 19 | W13: 20 | X13: 21 | Y13: 22 | Z13: 23 | AA13: 24 | AB13: 25
B14: Annuity | D14: =IF(D13<='SITE Model - INPUT PARAMETERS'!$C$42,PMT('SITE Model - INPUT PARAMETERS'!$C$41,'SITE Model - INPUT PARAMETERS'!$C$42,'SITE Model - INPUT PARAMETERS'!$C$40),0) -> -99319.163 | E14: =IF(E13<='SITE Model - INPUT PARAMETERS'!$C$42,PMT('SITE Model - INPUT PARAMETERS'!$C$41,'SITE Model - INPUT PARAMETERS'!$C$42,'SITE Model - INPUT PARAMETERS'!$C$40),0) -> -99319.163 | F14: =IF(F13<='SITE Model - INPUT PARAMETERS'!$C$42,PMT('SITE Model - INPUT PARAMETERS'!$C$41,'SITE Model - INPUT PARAMETERS'!$C$42,'SITE Model - INPUT PARAMETERS'!$C$40),0) -> -99319.163 | G14: =IF(G13<='SITE Model - INPUT PARAMETERS'!$C$42,PMT('SITE Model - INPUT PARAMETERS'!$C$41,'SITE Model - INPUT PARAMETERS'!$C$42,'SITE Model - INPUT PARAMETERS'!$C$40),0) -> -99319.163 | H14: =IF(H13<='SITE Model - INPUT PARAMETERS'!$C$42,PMT('SITE Model - INPUT PARAMETERS'!$C$41,'SITE Model - INPUT PARAMETERS'!$C$42,'SITE Model - INPUT PARAMETERS'!$C$40),0) -> -99319.163 | I14: =IF(I13<='SITE Model - INPUT PARAMETERS'!$C$42,PMT('SITE Model - INPUT PARAMETERS'!$C$41,'SITE Model - INPUT PARAMETERS'!$C$42,'SITE Model - INPUT PARAMETERS'!$C$40),0) -> 0 | J14: =IF(J13<='SITE Model - INPUT PARAMETERS'!$C$42,PMT('SITE Model - INPUT PARAMETERS'!$C$41,'SITE Model - INPUT PARAMETERS'!$C$42,'SITE Model - INPUT PARAMETERS'!$C$40),0) -> 0 | K14: =IF(K13<='SITE Model - INPUT PARAMETERS'!$C$42,PMT('SITE Model - INPUT PARAMETERS'!$C$41,'SITE Model - INPUT PARAMETERS'!$C$42,'SITE Model - INPUT PARAMETERS'!$C$40),0) -> 0 | ... M14: =IF(M13<='SITE Model - INPUT PARAMETERS'!$C$42,PMT('SITE Model - INPUT PARAMETERS'!$C$41,'SITE Model - INPUT PARAMETERS'!$C$42,'SITE Model - INPUT PARAMETERS'!$C$40),0) -> 0
B15: Amortization of capital | D15: =IF(D13<='SITE Model - INPUT PARAMETERS'!$C$42,PPMT('SITE Model - INPUT PARAMETERS'!$C$41,D13,'SITE Model - INPUT PARAMETERS'!$C$42,'SITE Model - INPUT PARAMETERS'!$C$40),0) -> -77819.163 | E15: =IF(E13<='SITE Model - INPUT PARAMETERS'!$C$42,PPMT('SITE Model - INPUT PARAMETERS'!$C$41,E13,'SITE Model - INPUT PARAMETERS'!$C$42,'SITE Model - INPUT PARAMETERS'!$C$40),0) -> -81710.121 | F15: =IF(F13<='SITE Model - INPUT PARAMETERS'!$C$42,PPMT('SITE Model - INPUT PARAMETERS'!$C$41,F13,'SITE Model - INPUT PARAMETERS'!$C$42,'SITE Model - INPUT PARAMETERS'!$C$40),0) -> -85795.627 | G15: =IF(G13<='SITE Model - INPUT PARAMETERS'!$C$42,PPMT('SITE Model - INPUT PARAMETERS'!$C$41,G13,'SITE Model - INPUT PARAMETERS'!$C$42,'SITE Model - INPUT PARAMETERS'!$C$40),0) -> -90085.409 | H15: =IF(H13<='SITE Model - INPUT PARAMETERS'!$C$42,PPMT('SITE Model - INPUT PARAMETERS'!$C$41,H13,'SITE Model - INPUT PARAMETERS'!$C$42,'SITE Model - INPUT PARAMETERS'!$C$40),0) -> -94589.679 | I15: =IF(I13<='SITE Model - INPUT PARAMETERS'!$C$42,PPMT('SITE Model - INPUT PARAMETERS'!$C$41,I13,'SITE Model - INPUT PARAMETERS'!$C$42,'SITE Model - INPUT PARAMETERS'!$C$40),0) -> 0 | J15: =IF(J13<='SITE Model - INPUT PARAMETERS'!$C$42,PPMT('SITE Model - INPUT PARAMETERS'!$C$41,J13,'SITE Model - INPUT PARAMETERS'!$C$42,'SITE Model - INPUT PARAMETERS'!$C$40),0) -> 0 | K15: =IF(K13<='SITE Model - INPUT PARAMETERS'!$C$42,PPMT('SITE Model - INPUT PARAMETERS'!$C$41,K13,'SITE Model - INPUT PARAMETERS'!$C$42,'SITE Model - INPUT PARAMETERS'!$C$40),0) -> 0 | ... M15: =IF(M13<='SITE Model - INPUT PARAMETERS'!$C$42,PPMT('SITE Model - INPUT PARAMETERS'!$C$41,M13,'SITE Model - INPUT PARAMETERS'!$C$42,'SITE Model - INPUT PARAMETERS'!$C$40),0) -> 0
B16: Interest payments | D16: =D14-D15 -> -21500 | E16: =E14-E15 -> -17609.042 | F16: =F14-F15 -> -13523.536 | G16: =G14-G15 -> -9233.7544 | H16: =H14-H15 -> -4729.484 | I16: =I14-I15 -> 0 | J16: =J14-J15 -> 0 | K16: =K14-K15 -> 0 | ... M16: =M14-M15 -> 0
B17: Debt outstanding | D17: ='SITE Model - INPUT PARAMETERS'!C40+D15 -> 352180.84 | E17: =D17+E15 -> 270470.72 | F17: =E17+F15 -> 184675.09 | G17: =F17+G15 -> 94589.679 | H17: =G17+H15 -> 1.3096724e-10 | I17: =H17+I15 -> 1.3096724e-10 | J17: =I17+J15 -> 1.3096724e-10 | K17: =J17+K15 -> 1.3096724e-10 | L17: =K17+L15 -> 1.3096724e-10 | M17: =L17+M15 -> 1.3096724e-10
B20: banking loan | D20: 1 | E20: 2 | F20: 3 | G20: 4 | H20: 5 | I20: 6 | J20: 7 | K20: 8 | L20: 9 | M20: 10 | N20: 11 | O20: 12 | P20: 13 | Q20: 14 | R20: 15 | S20: 16 | T20: 17 | U20: 18 | V20: 19 | W20: 20 | X20: 21 | Y20: 22 | Z20: 23 | AA20: 24 | AB20: 25
B21: Annuity | D21: =IF(D20<='SITE Model - INPUT PARAMETERS'!$C$45,PMT('SITE Model - INPUT PARAMETERS'!$C$44,'SITE Model - INPUT PARAMETERS'!$C$45,'SITE Model - INPUT PARAMETERS'!$C$43),0) -> -11231.356 | E21: =IF(E20<='SITE Model - INPUT PARAMETERS'!$C$45,PMT('SITE Model - INPUT PARAMETERS'!$C$44,'SITE Model - INPUT PARAMETERS'!$C$45,'SITE Model - INPUT PARAMETERS'!$C$43),0) -> -11231.356 | F21: =IF(F20<='SITE Model - INPUT PARAMETERS'!$C$45,PMT('SITE Model - INPUT PARAMETERS'!$C$44,'SITE Model - INPUT PARAMETERS'!$C$45,'SITE Model - INPUT PARAMETERS'!$C$43),0) -> -11231.356 | G21: =IF(G20<='SITE Model - INPUT PARAMETERS'!$C$45,PMT('SITE Model - INPUT PARAMETERS'!$C$44,'SITE Model - INPUT PARAMETERS'!$C$45,'SITE Model - INPUT PARAMETERS'!$C$43),0) -> -11231.356 | H21: =IF(H20<='SITE Model - INPUT PARAMETERS'!$C$45,PMT('SITE Model - INPUT PARAMETERS'!$C$44,'SITE Model - INPUT PARAMETERS'!$C$45,'SITE Model - INPUT PARAMETERS'!$C$43),0) -> -11231.356 | I21: =IF(I20<='SITE Model - INPUT PARAMETERS'!$C$45,PMT('SITE Model - INPUT PARAMETERS'!$C$44,'SITE Model - INPUT PARAMETERS'!$C$45,'SITE Model - INPUT PARAMETERS'!$C$43),0) -> 0 | J21: =IF(J20<='SITE Model - INPUT PARAMETERS'!$C$45,PMT('SITE Model - INPUT PARAMETERS'!$C$44,'SITE Model - INPUT PARAMETERS'!$C$45,'SITE Model - INPUT PARAMETERS'!$C$43),0) -> 0 | K21: =IF(K20<='SITE Model - INPUT PARAMETERS'!$C$45,PMT('SITE Model - INPUT PARAMETERS'!$C$44,'SITE Model - INPUT PARAMETERS'!$C$45,'SITE Model - INPUT PARAMETERS'!$C$43),0) -> 0 | ... M21: =IF(M20<='SITE Model - INPUT PARAMETERS'!$C$45,PMT('SITE Model - INPUT PARAMETERS'!$C$44,'SITE Model - INPUT PARAMETERS'!$C$45,'SITE Model - INPUT PARAMETERS'!$C$43),0) -> 0
B22: Amortization of capital | D22: =IF(D20<='SITE Model - INPUT PARAMETERS'!$C$45,PPMT('SITE Model - INPUT PARAMETERS'!$C$44,D20,'SITE Model - INPUT PARAMETERS'!$C$45,'SITE Model - INPUT PARAMETERS'!$C$43),0) -> -9231.3557 | E22: =IF(E20<='SITE Model - INPUT PARAMETERS'!$C$45,PPMT('SITE Model - INPUT PARAMETERS'!$C$44,E20,'SITE Model - INPUT PARAMETERS'!$C$45,'SITE Model - INPUT PARAMETERS'!$C$43),0) -> -9600.6099 | F22: =IF(F20<='SITE Model - INPUT PARAMETERS'!$C$45,PPMT('SITE Model - INPUT PARAMETERS'!$C$44,F20,'SITE Model - INPUT PARAMETERS'!$C$45,'SITE Model - INPUT PARAMETERS'!$C$43),0) -> -9984.6343 | G22: =IF(G20<='SITE Model - INPUT PARAMETERS'!$C$45,PPMT('SITE Model - INPUT PARAMETERS'!$C$44,G20,'SITE Model - INPUT PARAMETERS'!$C$45,'SITE Model - INPUT PARAMETERS'!$C$43),0) -> -10384.02 | H22: =IF(H20<='SITE Model - INPUT PARAMETERS'!$C$45,PPMT('SITE Model - INPUT PARAMETERS'!$C$44,H20,'SITE Model - INPUT PARAMETERS'!$C$45,'SITE Model - INPUT PARAMETERS'!$C$43),0) -> -10799.38 | I22: =IF(I20<='SITE Model - INPUT PARAMETERS'!$C$45,PPMT('SITE Model - INPUT PARAMETERS'!$C$44,I20,'SITE Model - INPUT PARAMETERS'!$C$45,'SITE Model - INPUT PARAMETERS'!$C$43),0) -> 0 | J22: =IF(J20<='SITE Model - INPUT PARAMETERS'!$C$45,PPMT('SITE Model - INPUT PARAMETERS'!$C$44,J20,'SITE Model - INPUT PARAMETERS'!$C$45,'SITE Model - INPUT PARAMETERS'!$C$43),0) -> 0 | K22: =IF(K20<='SITE Model - INPUT PARAMETERS'!$C$45,PPMT('SITE Model - INPUT PARAMETERS'!$C$44,K20,'SITE Model - INPUT PARAMETERS'!$C$45,'SITE Model - INPUT PARAMETERS'!$C$43),0) -> 0 | ... M22: =IF(M20<='SITE Model - INPUT PARAMETERS'!$C$45,PPMT('SITE Model - INPUT PARAMETERS'!$C$44,M20,'SITE Model - INPUT PARAMETERS'!$C$45,'SITE Model - INPUT PARAMETERS'!$C$43),0) -> 0
B23: Interest payments | D23: =D21-D22 -> -2000 | E23: =E21-E22 -> -1630.7458 | F23: =F21-F22 -> -1246.7214 | G23: =G21-G22 -> -847.33601 | H23: =H21-H22 -> -431.97522 | I23: =I21-I22 -> 0 | J23: =J21-J22 -> 0 | K23: =K21-K22 -> 0 | ... M23: =M21-M22 -> 0
B24: Debt outstanding | D24: ='SITE Model - INPUT PARAMETERS'!C43+D22 -> 40768.644 | E24: =D24+E22 -> 31168.034 | F24: =E24+F22 -> 21183.4 | G24: =F24+G22 -> 10799.38 | H24: =G24+H22 -> 0 | I24: =H24+I22 -> 0 | J24: =I24+J22 -> 0 | K24: =J24+K22 -> 0 | L24: =K24+L22 -> 0 | M24: =L24+M22 -> 0
B27: Total investment | D27: 1 | E27: 2 | F27: 3 | G27: 4 | H27: 5 | I27: 6 | J27: 7 | K27: 8 | L27: 9 | M27: 10 | N27: 11 | O27: 12 | P27: 13 | Q27: 14 | R27: 15 | S27: 16 | T27: 17 | U27: 18 | V27: 19 | W27: 20 | X27: 21 | Y27: 22 | Z27: 23 | AA27: 24 | AB27: 25
B28: Annuity | D28: =+D14+D21 -> -110550.52 | E28: =+E14+E21 -> -110550.52 | F28: =+F14+F21 -> -110550.52 | G28: =+G14+G21 -> -110550.52 | H28: =+H14+H21 -> -110550.52 | I28: =+I14+I21 -> 0 | J28: =+J14+J21 -> 0 | K28: =+K14+K21 -> 0 | ... M28: =+M14+M21 -> 0
B29: Amortization of capital | D29: =+D15+D22 -> -87050.519 | E29: =+E15+E22 -> -91310.731 | F29: =+F15+F22 -> -95780.262 | G29: =+G15+G22 -> -100469.43 | H29: =+H15+H22 -> -105389.06 | I29: =+I15+I22 -> 0 | J29: =+J15+J22 -> 0 | K29: =+K15+K22 -> 0 | ... M29: =+M15+M22 -> 0
B30: Interest payments | D30: =+D16+D23 -> -23500 | E30: =+E16+E23 -> -19239.788 | F30: =+F16+F23 -> -14770.257 | G30: =+G16+G23 -> -10081.09 | H30: =+H16+H23 -> -5161.4592 | I30: =+I16+I23 -> 0 | J30: =+J16+J23 -> 0 | K30: =+K16+K23 -> 0 | ... M30: =+M16+M23 -> 0
B31: Debt outstanding | D31: =+D17+D24 -> 392949.48 | E31: =+E17+E24 -> 301638.75 | F31: =+F17+F24 -> 205858.49 | G31: =+G17+G24 -> 105389.06 | H31: =+H17+H24 -> 1.3096724e-10 | I31: =+I17+I24 -> 1.3096724e-10 | J31: =+J17+J24 -> 1.3096724e-10 | K31: =+K17+K24 -> 1.3096724e-10 | ... M31: =+M17+M24 -> 1.3096724e-10
B35: Operating Account | D35: 1 | E35: =D35+1 -> 2 | F35: =E35+1 -> 3 | G35: =F35+1 -> 4 | H35: =G35+1 -> 5 | I35: =H35+1 -> 6 | J35: =I35+1 -> 7 | K35: =J35+1 -> 8 | L35: =K35+1 -> 9 | ... AB35: =AA35+1 -> 25
B38: Revenue , percentage of achievement/year ( percentage on each production) | D38: 1 | E38: 1 | F38: 1 | G38: 1 | H38: 1 | I38: 1 | J38: 1 | K38: 1 | L38: 1 | M38: 1 | N38: 1 | O38: 1 | P38: 1 | Q38: 1 | R38: 1 | S38: 1 | T38: 1 | U38: 1 | V38: 1 | W38: 1 | X38: 1 | Y38: 1 | Z38: 1 | AA38: 1 | AB38: 1
B39: Total revenues | D39: =SUM(D40:D42) -> 2095200 | E39: =SUM(E40:E42) -> 4024872 | F39: =SUM(F40:F42) -> 5958624.7 | G39: =SUM(G40:G42) -> 7867344.7 | H39: =SUM(H40:H42) -> 10047618 | I39: =SUM(I40:I42) -> 10148094 | J39: =SUM(J40:J42) -> 10249575 | K39: =SUM(K40:K42) -> 10352071 | ... AB39: =SUM(AB40:AB42) -> 12260004
B40: Food | D40: =+'Site Geneva revenues A'!D18+'Site Geneva revenues B'!D21+'Site Geneva revenues C'!D21 -> 1708080 | E40: =+'Site Geneva revenues A'!E18+'Site Geneva revenues B'!E21+'Site Geneva revenues C'!E21+'Site Zurich revenues A '!E18+'Site Zurch revenues B '!E18+'Site Zurich revenues C '!E18 -> 3246760.8 | F40: =+'Site Geneva revenues A'!F18+'Site Geneva revenues B'!F21+'Site Geneva revenues C'!F21+'Site Zurich revenues A '!E18+'Site Zurch revenues B '!E18+'Site Zurich revenues C '!E18+'Site Loc 3 revenues A '!F18+'Site Loc 3 revenues B '!F18+'Site Loc 3 revenues C '!F18 -> 4785612.4 | G40: =F40+'Site Loc 4 revenues A '!G18+'Site Loc 4 revenues B '!G18+'Site Loc 4 revenues C '!G18 -> 6307212.4 | H40: =+'Site Geneva revenues A'!H18+'Site Geneva revenues B'!H21+'Site Geneva revenues C'!H21+G40 -> 8084647.3 | I40: =H40*(1+'SITE Model - INPUT PARAMETERS'!$C$29) -> 8165493.8 | J40: =I40*(1+'SITE Model - INPUT PARAMETERS'!$C$29) -> 8247148.7 | K40: =J40*(1+'SITE Model - INPUT PARAMETERS'!$C$29) -> 8329620.2 | L40: =K40*(1+'SITE Model - INPUT PARAMETERS'!$C$29) -> 8412916.4 | M40: =L40*(1+'SITE Model - INPUT PARAMETERS'!$C$29) -> 8497045.6 | N40: =M40*(1+'SITE Model - INPUT PARAMETERS'!$C$29) -> 8582016 | O40: =N40*(1+'SITE Model - INPUT PARAMETERS'!$C$29) -> 8667836.2 | P40: =O40*(1+'SITE Model - INPUT PARAMETERS'!$C$29) -> 8754514.5 | ... AB40: =AA40*(1+'SITE Model - INPUT PARAMETERS'!$C$29) -> 9864806.1
B41: Beverage | D41: =+'Site Geneva revenues A'!D19+'Site Geneva revenues B'!D19+'Site Geneva revenues C'!D19 -> 213600 | E41: =+'Site Geneva revenues A'!E19+'Site Geneva revenues B'!E19+'Site Geneva revenues C'!E19+'Site Zurich revenues A '!E19+'Site Zurch revenues B '!E19+'Site Zurich revenues C '!E19 -> 429336 | F41: =+'Site Geneva revenues A'!F19+'Site Geneva revenues B'!F19+'Site Geneva revenues C'!F19+'Site Zurich revenues A '!F19+'Site Zurch revenues B '!F19+'Site Zurich revenues C '!F19+'Site Loc 3 revenues A '!F19+'Site Loc 3 revenues B '!F19+'Site Loc 3 revenues C '!F19 -> 647229.36 | G41: =F41+'Site Loc 4 revenues A '!G19+'Site Loc 4 revenues B '!G19+'Site Loc 4 revenues C '!G19 -> 860829.36 | H41: =+'Site Geneva revenues A'!H19+'Site Geneva revenues B'!H19+'Site Geneva revenues C'!H19+G41 -> 1083102.4 | I41: =H41*(1+'SITE Model - INPUT PARAMETERS'!$C$29) -> 1093933.4 | J41: =I41*(1+'SITE Model - INPUT PARAMETERS'!$C$29) -> 1104872.7 | K41: =J41*(1+'SITE Model - INPUT PARAMETERS'!$C$29) -> 1115921.5 | L41: =K41*(1+'SITE Model - INPUT PARAMETERS'!$C$29) -> 1127080.7 | M41: =L41*(1+'SITE Model - INPUT PARAMETERS'!$C$29) -> 1138351.5 | N41: =M41*(1+'SITE Model - INPUT PARAMETERS'!$C$29) -> 1149735 | O41: =N41*(1+'SITE Model - INPUT PARAMETERS'!$C$29) -> 1161232.3 | P41: =O41*(1+'SITE Model - INPUT PARAMETERS'!$C$29) -> 1172844.7 | ... AB41: =AA41*(1+'SITE Model - INPUT PARAMETERS'!$C$29) -> 1321590.7
B42: Service charges | D42: =+'Site Geneva revenues A'!D20+'Site Geneva revenues B'!D20+'Site Geneva revenues C'!D20 -> 173520 | E42: =+'Site Geneva revenues A'!E20+'Site Geneva revenues B'!E20+'Site Geneva revenues C'!E20+'Site Zurich revenues A '!E20+'Site Zurch revenues B '!E20+'Site Zurich revenues C '!E20 -> 348775.2 | F42: =+'Site Geneva revenues A'!F20+'Site Geneva revenues B'!F20+'Site Geneva revenues C'!F20+'Site Zurich revenues A '!F20+'Site Zurch revenues B '!F20+'Site Zurich revenues C '!F20+'Site Loc 3 revenues A '!F20+'Site Loc 3 revenues B '!F20+'Site Loc 3 revenues C '!F20 -> 525782.95 | G42: =F42+'Site Loc 4 revenues A '!G20+'Site Loc 4 revenues B '!G20+'Site Loc 4 revenues C '!G20 -> 699302.95 | H42: =+'Site Geneva revenues A'!H20+'Site Geneva revenues B'!H20+'Site Geneva revenues C'!H20+G42 -> 879868.56 | I42: =H42*(1+'SITE Model - INPUT PARAMETERS'!$C$29) -> 888667.25 | J42: =I42*(1+'SITE Model - INPUT PARAMETERS'!$C$29) -> 897553.92 | K42: =J42*(1+'SITE Model - INPUT PARAMETERS'!$C$29) -> 906529.46 | L42: =K42*(1+'SITE Model - INPUT PARAMETERS'!$C$29) -> 915594.75 | M42: =L42*(1+'SITE Model - INPUT PARAMETERS'!$C$29) -> 924750.7 | N42: =M42*(1+'SITE Model - INPUT PARAMETERS'!$C$29) -> 933998.21 | O42: =N42*(1+'SITE Model - INPUT PARAMETERS'!$C$29) -> 943338.19 | P42: =O42*(1+'SITE Model - INPUT PARAMETERS'!$C$29) -> 952771.57 | ... AB42: =AA42*(1+'SITE Model - INPUT PARAMETERS'!$C$29) -> 1073606.9
B43: Total Personnel costs | D43: ='SITE Model - INPUT PARAMETERS'!L21 -> 946000 | E43: =D43*(1+'SITE Model - INPUT PARAMETERS'!C29)*2 -> 1910920 | F43: =E43*(1+'SITE Model - INPUT PARAMETERS'!C29)+D43 -> 2876029.2 | G43: =F43*(1+'SITE Model - INPUT PARAMETERS'!C29)+D43 -> 3850789.5 | H43: =G43*(1+'SITE Model - INPUT PARAMETERS'!C29)+D43 -> 4835297.4 | I43: =H43*(1+'SITE Model - INPUT PARAMETERS'!$C$29) -> 4883650.4 | J43: =I43*(1+'SITE Model - INPUT PARAMETERS'!$C$29) -> 4932486.9 | K43: =J43*(1+'SITE Model - INPUT PARAMETERS'!$C$29) -> 4981811.7 | L43: =K43*(1+'SITE Model - INPUT PARAMETERS'!$C$29) -> 5031629.9 | M43: =L43*(1+'SITE Model - INPUT PARAMETERS'!$C$29) -> 5081946.1 | N43: =M43*(1+'SITE Model - INPUT PARAMETERS'!$C$29) -> 5132765.6 | O43: =N43*(1+'SITE Model - INPUT PARAMETERS'!$C$29) -> 5184093.3 | P43: =O43*(1+'SITE Model - INPUT PARAMETERS'!$C$29) -> 5235934.2 | ... AB43: =AA43*(1+'SITE Model - INPUT PARAMETERS'!$C$29) -> 5899981.7
B44: implementation of the project | D44: =+'Site Geneva revenues A'!D17 -> 1 | E44: =+'Site Geneva revenues A'!E17 -> 1 | F44: =+'Site Geneva revenues A'!F17 -> 1 | G44: =+'Site Geneva revenues A'!G17 -> 1 | H44: =+'Site Geneva revenues A'!H17 -> 1 | I44: =+'Site Geneva revenues A'!I17 -> 1 | J44: =+'Site Geneva revenues A'!J17 -> 1 | K44: =+'Site Geneva revenues A'!K17 -> 1 | ... AB44: =+'Site Geneva revenues A'!AB17 -> 1
B45: raw material for food | D45: =D40*'SITE Model - INPUT PARAMETERS'!C15 -> 170808 | E45: =D45*(1+'SITE Model - INPUT PARAMETERS'!C29)*2 -> 345032.16 | F45: =E45*(1+'SITE Model - INPUT PARAMETERS'!C29)+D45 -> 519290.48 | G45: =F45*(1+'SITE Model - INPUT PARAMETERS'!C29)+D45 -> 695291.39 | H45: =G45*(1+'SITE Model - INPUT PARAMETERS'!C29)+D45 -> 873052.3 | I45: =H45*(1+'SITE Model - INPUT PARAMETERS'!$C$29) -> 881782.82 | J45: =I45*(1+'SITE Model - INPUT PARAMETERS'!$C$29) -> 890600.65 | K45: =J45*(1+'SITE Model - INPUT PARAMETERS'!$C$29) -> 899506.66 | L45: =K45*(1+'SITE Model - INPUT PARAMETERS'!$C$29) -> 908501.72 | M45: =L45*(1+'SITE Model - INPUT PARAMETERS'!$C$29) -> 917586.74 | N45: =M45*(1+'SITE Model - INPUT PARAMETERS'!$C$29) -> 926762.61 | O45: =N45*(1+'SITE Model - INPUT PARAMETERS'!$C$29) -> 936030.24 | P45: =O45*(1+'SITE Model - INPUT PARAMETERS'!$C$29) -> 945390.54 | ... AB45: =AA45*(1+'SITE Model - INPUT PARAMETERS'!$C$29) -> 1065289.7
B46: raw material for beverage | D46: =D41*'SITE Model - INPUT PARAMETERS'!C16 -> 32040 | E46: =D46*(1+'SITE Model - INPUT PARAMETERS'!C29)*2 -> 64720.8 | F46: =E46*(1+'SITE Model - INPUT PARAMETERS'!C29)+D46 -> 97408.008 | G46: =F46*(1+'SITE Model - INPUT PARAMETERS'!C29)+D46 -> 130422.09 | H46: =G46*(1+'SITE Model - INPUT PARAMETERS'!C29)+D46 -> 163766.31 | I46: =H46*(1+'SITE Model - INPUT PARAMETERS'!$C$29) -> 165403.97 | J46: =I46*(1+'SITE Model - INPUT PARAMETERS'!$C$29) -> 167058.01 | K46: =J46*(1+'SITE Model - INPUT PARAMETERS'!$C$29) -> 168728.59 | L46: =K46*(1+'SITE Model - INPUT PARAMETERS'!$C$29) -> 170415.88 | M46: =L46*(1+'SITE Model - INPUT PARAMETERS'!$C$29) -> 172120.04 | N46: =M46*(1+'SITE Model - INPUT PARAMETERS'!$C$29) -> 173841.24 | O46: =N46*(1+'SITE Model - INPUT PARAMETERS'!$C$29) -> 175579.65 | P46: =O46*(1+'SITE Model - INPUT PARAMETERS'!$C$29) -> 177335.45 | ... AB46: =AA46*(1+'SITE Model - INPUT PARAMETERS'!$C$29) -> 199826.02
B47: operating expences+ Rents | D47: ='SITE Model - INPUT PARAMETERS'!G17+'SITE Model - INPUT PARAMETERS'!G18+'SITE Model - INPUT PARAMETERS'!G19 -> 300000 | E47: =D47*(1+'SITE Model - INPUT PARAMETERS'!C29)*2 -> 606000 | F47: =E47*(1+'SITE Model - INPUT PARAMETERS'!C29)+D47 -> 912060 | G47: =F47*(1+'SITE Model - INPUT PARAMETERS'!C29)+D47 -> 1221180.6 | H47: =G47*(1+'SITE Model - INPUT PARAMETERS'!C29)+D47 -> 1533392.4 | I47: =H47*(1+'SITE Model - INPUT PARAMETERS'!$C$29) -> 1548726.3 | J47: =I47*(1+'SITE Model - INPUT PARAMETERS'!$C$29) -> 1564213.6 | K47: =J47*(1+'SITE Model - INPUT PARAMETERS'!$C$29) -> 1579855.7 | L47: =K47*(1+'SITE Model - INPUT PARAMETERS'!$C$29) -> 1595654.3 | M47: =L47*(1+'SITE Model - INPUT PARAMETERS'!$C$29) -> 1611610.8 | N47: =M47*(1+'SITE Model - INPUT PARAMETERS'!$C$29) -> 1627726.9 | O47: =N47*(1+'SITE Model - INPUT PARAMETERS'!$C$29) -> 1644004.2 | P47: =O47*(1+'SITE Model - INPUT PARAMETERS'!$C$29) -> 1660444.2 | ... AB47: =AA47*(1+'SITE Model - INPUT PARAMETERS'!$C$29) -> 1871030.1
B48: Administration | D48: ='SITE Model - INPUT PARAMETERS'!G16 -> 120000 | E48: =D48*(1+'SITE Model - INPUT PARAMETERS'!C29)*2 -> 242400 | F48: =E48*(1+'SITE Model - INPUT PARAMETERS'!C29)+D48 -> 364824 | G48: =F48*(1+'SITE Model - INPUT PARAMETERS'!C29)+D48 -> 488472.24 | H48: =G48*(1+'SITE Model - INPUT PARAMETERS'!C29)+D48 -> 613356.96 | I48: =H48*(1+'SITE Model - INPUT PARAMETERS'!$C$29) -> 619490.53 | J48: =I48*(1+'SITE Model - INPUT PARAMETERS'!$C$29) -> 625685.44 | K48: =J48*(1+'SITE Model - INPUT PARAMETERS'!$C$29) -> 631942.29 | L48: =K48*(1+'SITE Model - INPUT PARAMETERS'!$C$29) -> 638261.71 | M48: =L48*(1+'SITE Model - INPUT PARAMETERS'!$C$29) -> 644644.33 | N48: =M48*(1+'SITE Model - INPUT PARAMETERS'!$C$29) -> 651090.78 | O48: =N48*(1+'SITE Model - INPUT PARAMETERS'!$C$29) -> 657601.68 | P48: =O48*(1+'SITE Model - INPUT PARAMETERS'!$C$29) -> 664177.7 | ... AB48: =AA48*(1+'SITE Model - INPUT PARAMETERS'!$C$29) -> 748412.06
B49: Contigencies | D49: ='SITE Model - INPUT PARAMETERS'!G20 -> 50000 | E49: =D49*(1+'SITE Model - INPUT PARAMETERS'!C29)*2 -> 101000 | F49: =E49*(1+'SITE Model - INPUT PARAMETERS'!C29)+D49 -> 152010 | G49: =F49*(1+'SITE Model - INPUT PARAMETERS'!C29)+D49 -> 203530.1 | H49: =G49*(1+'SITE Model - INPUT PARAMETERS'!C29)+D49 -> 255565.4 | I49: =H49*(1+'SITE Model - INPUT PARAMETERS'!$C$29) -> 258121.06 | J49: =I49*(1+'SITE Model - INPUT PARAMETERS'!$C$29) -> 260702.27 | K49: =J49*(1+'SITE Model - INPUT PARAMETERS'!$C$29) -> 263309.29 | L49: =K49*(1+'SITE Model - INPUT PARAMETERS'!$C$29) -> 265942.38 | M49: =L49*(1+'SITE Model - INPUT PARAMETERS'!$C$29) -> 268601.8 | N49: =M49*(1+'SITE Model - INPUT PARAMETERS'!$C$29) -> 271287.82 | O49: =N49*(1+'SITE Model - INPUT PARAMETERS'!$C$29) -> 274000.7 | P49: =O49*(1+'SITE Model - INPUT PARAMETERS'!$C$29) -> 276740.71 | ... AB49: =AA49*(1+'SITE Model - INPUT PARAMETERS'!$C$29) -> 311838.36
B50: Costs | D50: =SUM(D45:D49) -> 672848 | E50: =SUM(E45:E49) -> 1359153 | F50: =SUM(F45:F49) -> 2045592.5 | G50: =SUM(G45:G49) -> 2738896.4 | H50: =SUM(H45:H49) -> 3439133.4 | I50: =SUM(I45:I49) -> 3473524.7 | J50: =SUM(J45:J49) -> 3508260 | K50: =SUM(K45:K49) -> 3543342.6 | ... AB50: =SUM(AB45:AB49) -> 4196396.3
B51: Total Operating Expenses updated with inflaction | D51: =D43+D50 -> 1618848 | E51: =E43+E50 -> 3270073 | F51: =F43+F50 -> 4921621.7 | G51: =G43+G50 -> 6589685.9 | H51: =H43+H50 -> 8274430.8 | I51: =I43+I50 -> 8357175.1 | J51: =J43+J50 -> 8440746.8 | K51: =K43+K50 -> 8525154.3 | ... AB51: =AB43+AB50 -> 10096378
B53: EBITDA | D53: =D39-D51 -> 476352 | E53: =E39-E51 -> 754799.04 | F53: =F39-F51 -> 1037003 | G53: =G39-G51 -> 1277658.8 | H53: =H39-H51 -> 1773187.5 | I53: =I39-I51 -> 1790919.4 | J53: =J39-J51 -> 1808828.5 | K53: =K39-K51 -> 1826916.8 | ... AB53: =AB39-AB51 -> 2163625.7
B54: Depreciation | C54: 10 | D54: =IF(D35<=$C$54,'SITE Model - INPUT PARAMETERS'!$C$35/$C$54,0) -> 43000 | E54: =IF(E35<=$C$54,'SITE Model - INPUT PARAMETERS'!$C$35/$C$54,0) -> 43000 | F54: =IF(F35<=$C$54,'SITE Model - INPUT PARAMETERS'!$C$35/$C$54,0) -> 43000 | G54: =IF(G35<=$C$54,'SITE Model - INPUT PARAMETERS'!$C$35/$C$54,0) -> 43000 | H54: =IF(H35<=$C$54,'SITE Model - INPUT PARAMETERS'!$C$35/$C$54,0) -> 43000 | I54: =IF(I35<=$C$54,'SITE Model - INPUT PARAMETERS'!$C$35/$C$54,0) -> 43000 | J54: =IF(J35<=$C$54,'SITE Model - INPUT PARAMETERS'!$C$35/$C$54,0) -> 43000 | K54: =IF(K35<=$C$54,'SITE Model - INPUT PARAMETERS'!$C$35/$C$54,0) -> 43000 | ... M54: =IF(M35<=$C$54,'SITE Model - INPUT PARAMETERS'!$C$35/$C$54,0) -> 43000 | N54: 420000 | O54: =IF(O35<=$C$54,'SITE Model - INPUT PARAMETERS'!$C$35/$C$54,0) -> 0 | P54: =IF(P35<=$C$54,'SITE Model - INPUT PARAMETERS'!$C$35/$C$54,0) -> 0 | Q54: =IF(Q35<=$C$54,'SITE Model - INPUT PARAMETERS'!$C$35/$C$54,0) -> 0 | R54: =IF(R35<=$C$54,'SITE Model - INPUT PARAMETERS'!$C$35/$C$54,0) -> 0 | S54: =IF(S35<=$C$54,'SITE Model - INPUT PARAMETERS'!$C$35/$C$54,0) -> 0 | T54: =IF(T35<=$C$54,'SITE Model - INPUT PARAMETERS'!$C$35/$C$54,0) -> 0 | U54: =IF(U35<=$C$54,'SITE Model - INPUT PARAMETERS'!$C$35/$C$54,0) -> 0 | V54: =IF(V35<=$C$54,'SITE Model - INPUT PARAMETERS'!$C$35/$C$54,0) -> 0 | ... AB54: =IF(AB35<=$C$54,'SITE Model - INPUT PARAMETERS'!$C$35/$C$54,0) -> 0
B55: EBIT | D55: =D53-D54 -> 433352 | E55: =E53-E54 -> 711799.04 | F55: =F53-F54 -> 994003.03 | G55: =G53-G54 -> 1234658.8 | H55: =H53-H54 -> 1730187.5 | I55: =I53-I54 -> 1747919.4 | J55: =J53-J54 -> 1765828.5 | K55: =K53-K54 -> 1783916.8 | ... AB55: =AB53-AB54 -> 2163625.7
B56: Interest expenses on senior debt | D56: =D30 -> -23500 | E56: =E30 -> -19239.788 | F56: =F30 -> -14770.257 | G56: =G30 -> -10081.09 | H56: =H30 -> -5161.4592 | I56: =I30 -> 0 | J56: =J30 -> 0 | K56: =K30 -> 0 | ... AB56: =AB30 -> 0
B57: EBT | D57: =D55+D56 -> 409852 | E57: =E55+E56 -> 692559.25 | F57: =F55+F56 -> 979232.77 | G57: =G55+G56 -> 1224577.7 | H57: =H55+H56 -> 1725026 | I57: =I55+I56 -> 1747919.4 | J57: =J55+J56 -> 1765828.5 | K57: =K55+K56 -> 1783916.8 | ... AB57: =AB55+AB56 -> 2163625.7
B58: Corporate Tax | C58: 0.25 | D58: =+D91 -> 109633 | E58: =+E91 -> 195863.32 | F58: =+F91 -> 294943.65 | G58: =+G91 -> 378119.68 | H58: =+H91 -> 525381.72 | I58: =+I91 -> 534652.84 | J58: =+J91 -> 540106.87 | K58: =+K91 -> 545615.44 | ... AB58: =+AB91 -> 658906.06
B60: NET INCOME | D60: =D57-D58 -> 300219 | E60: =E57-E58 -> 496695.93 | F60: =F57-F58 -> 684289.12 | G60: =G57-G58 -> 846458.05 | H60: =H57-H58 -> 1199644.3 | I60: =I57-I58 -> 1213266.5 | J60: =J57-J58 -> 1225721.7 | K60: =K57-K58 -> 1238301.4 | ... AB60: =AB57-AB58 -> 1504719.6
...

Sheet Site Geneva revenues A
B2: PRODUCTION : based on assumptions
B4: Revenues A (Main)
C5: Food | D5: Beverage | E5: Service Charges | F5: Total income
B6: percentage | C6: 0.7 | D6: 0.2 | E6: 0.1
B8: Monthly average | C8: =80*22*40 -> 70400 | D8: =40*22*10 -> 8800 | E8: =(C8+D8)*E6 -> 7920 | F8: =SUM(C8:E8) -> 87120
B11: yearly average value | C11: =C8*12 -> 844800 | D11: =D8*12 -> 105600 | E11: =E8*12 -> 95040 | F11: =+E11+D11+C11 -> 1045440
B16: operating income (updated with inflaction) | D16: 1 | E16: =D16+1 -> 2 | F16: =E16+1 -> 3 | G16: =F16+1 -> 4 | H16: =G16+1 -> 5 | I16: =H16+1 -> 6 | J16: =I16+1 -> 7 | K16: =J16+1 -> 8 | L16: =K16+1 -> 9 | ... AB16: =AA16+1 -> 25
B17: implementation of the project | D17: 1 | E17: 1 | F17: 1 | G17: 1 | H17: 1 | I17: 1 | J17: 1 | K17: 1 | L17: 1 | M17: 1 | N17: 1 | O17: 1 | P17: 1 | Q17: 1 | R17: 1 | S17: 1 | T17: 1 | U17: 1 | V17: 1 | W17: 1 | X17: 1 | Y17: 1 | Z17: 1 | AA17: 1 | AB17: 1
B18: Food | D18: =+C11*D17 -> 844800 | E18: =+$D$18*E17*(1+'SITE Model - INPUT PARAMETERS'!$C$29)^(E$16-1) -> 853248 | F18: =+$D$18*F17*(1+'SITE Model - INPUT PARAMETERS'!$C$29)^(F$16-1) -> 861780.48 | G18: =+$D$18*G17*(1+'SITE Model - INPUT PARAMETERS'!$C$29)^(G$16-1) -> 870398.28 | H18: =+$D$18*H17*(1+'SITE Model - INPUT PARAMETERS'!$C$29)^(H$16-1) -> 879102.27 | I18: =+$D$18*I17*(1+'SITE Model - INPUT PARAMETERS'!$C$29)^(I$16-1) -> 887893.29 | J18: =+$D$18*J17*(1+'SITE Model - INPUT PARAMETERS'!$C$29)^(J$16-1) -> 896772.22 | K18: =+$D$18*K17*(1+'SITE Model - INPUT PARAMETERS'!$C$29)^(K$16-1) -> 905739.95 | L18: =+$D$18*L17*(1+'SITE Model - INPUT PARAMETERS'!$C$29)^(L$16-1) -> 914797.34 | ... AB18: =+$D$18*AB17*(1+'SITE Model - INPUT PARAMETERS'!$C$29)^(AB$16-1) -> 1072671.8
B19: Beverage | D19: =+D11*D17 -> 105600 | E19: =+$D$19*E17*(1+'SITE Model - INPUT PARAMETERS'!$C$29)^(E$16-1) -> 106656 | F19: =+$D$19*F17*(1+'SITE Model - INPUT PARAMETERS'!$C$29)^(F$16-1) -> 107722.56 | G19: =+$D$19*G17*(1+'SITE Model - INPUT PARAMETERS'!$C$29)^(G$16-1) -> 108799.79 | H19: =+$D$19*H17*(1+'SITE Model - INPUT PARAMETERS'!$C$29)^(H$16-1) -> 109887.78 | I19: =+$D$19*I17*(1+'SITE Model - INPUT PARAMETERS'!$C$29)^(I$16-1) -> 110986.66 | J19: =+$D$19*J17*(1+'SITE Model - INPUT PARAMETERS'!$C$29)^(J$16-1) -> 112096.53 | K19: =+$D$19*K17*(1+'SITE Model - INPUT PARAMETERS'!$C$29)^(K$16-1) -> 113217.49 | L19: =+$D$19*L17*(1+'SITE Model - INPUT PARAMETERS'!$C$29)^(L$16-1) -> 114349.67 | ... AB19: =+$D$19*AB17*(1+'SITE Model - INPUT PARAMETERS'!$C$29)^(AB$16-1) -> 134083.98
B20: Service charges | D20: =+E11*D17 -> 95040 | E20: =+$D$20*E17*(1+'SITE Model - INPUT PARAMETERS'!$C$29)^(E$16-1) -> 95990.4 | F20: =+$D$20*F17*(1+'SITE Model - INPUT PARAMETERS'!$C$29)^(F$16-1) -> 96950.304 | G20: =+$D$20*G17*(1+'SITE Model - INPUT PARAMETERS'!$C$29)^(G$16-1) -> 97919.807 | H20: =+$D$20*H17*(1+'SITE Model - INPUT PARAMETERS'!$C$29)^(H$16-1) -> 98899.005 | I20: =+$D$20*I17*(1+'SITE Model - INPUT PARAMETERS'!$C$29)^(I$16-1) -> 99887.995 | J20: =+$D$20*J17*(1+'SITE Model - INPUT PARAMETERS'!$C$29)^(J$16-1) -> 100886.88 | K20: =+$D$20*K17*(1+'SITE Model - INPUT PARAMETERS'!$C$29)^(K$16-1) -> 101895.74 | L20: =+$D$20*L17*(1+'SITE Model - INPUT PARAMETERS'!$C$29)^(L$16-1) -> 102914.7 | ... AB20: =+$D$20*AB17*(1+'SITE Model - INPUT PARAMETERS'!$C$29)^(AB$16-1) -> 120675.58
B21: Total Revenues | D21: =SUM(D18:D20) -> 1045440 | E21: =SUM(E18:E20) -> 1055894.4 | F21: =SUM(F18:F20) -> 1066453.3 | G21: =SUM(G18:G20) -> 1077117.9 | H21: =SUM(H18:H20) -> 1087889.1 | I21: =SUM(I18:I20) -> 1098767.9 | J21: =SUM(J18:J20) -> 1109755.6 | K21: =SUM(K18:K20) -> 1120853.2 | ... AB21: =SUM(AB18:AB20) -> 1327431.4

Sheet Site Geneva revenues B
B2: PRODUCTION : based on assumptions
B4: Revenues B (HD)
C5: Food | D5: Beverage | E5: Service Charges | F5: Total income
B6: percentage | C6: 0.7 | D6: 0.2 | E6: 0.1
B8: Monthly average | C8: =40*22*30 -> 26400 | D8: =20*20*10 -> 4000 | E8: =(C8+D8)*E6 -> 3040 | F8: =SUM(C8:E8) -> 33440
B11: yearly average value | C11: =C8*12 -> 316800 | D11: =D8*12 -> 48000 | E11: =E8*12 -> 36480 | F11: =+E11+D11+C11 -> 401280
B16: operating income (updated with inflaction) | D16: 1 | E16: =D16+1 -> 2 | F16: =E16+1 -> 3 | G16: =F16+1 -> 4 | H16: =G16+1 -> 5 | I16: =H16+1 -> 6 | J16: =I16+1 -> 7 | K16: =J16+1 -> 8 | L16: =K16+1 -> 9 | ... AB16: =AA16+1 -> 25
B17: implementation of the project | D17: 1 | E17: 1 | F17: 1 | G17: 1 | H17: 1 | I17: 1 | J17: 1 | K17: 1 | L17: 1 | M17: 1 | N17: 1 | O17: 1 | P17: 1 | Q17: 1 | R17: 1 | S17: 1 | T17: 1 | U17: 1 | V17: 1 | W17: 1 | X17: 1 | Y17: 1 | Z17: 1 | AA17: 1 | AB17: 1
B18: Food | D18: =+C11*D17 -> 316800 | E18: =+$D$18*E17*(1+'SITE Model - INPUT PARAMETERS'!$C$29)^(E$16-1) -> 319968 | F18: =+$D$18*F17*(1+'SITE Model - INPUT PARAMETERS'!$C$29)^(F$16-1) -> 323167.68 | G18: =+$D$18*G17*(1+'SITE Model - INPUT PARAMETERS'!$C$29)^(G$16-1) -> 326399.36 | H18: =+$D$18*H17*(1+'SITE Model - INPUT PARAMETERS'!$C$29)^(H$16-1) -> 329663.35 | I18: =+$D$18*I17*(1+'SITE Model - INPUT PARAMETERS'!$C$29)^(I$16-1) -> 332959.98 | J18: =+$D$18*J17*(1+'SITE Model - INPUT PARAMETERS'!$C$29)^(J$16-1) -> 336289.58 | K18: =+$D$18*K17*(1+'SITE Model - INPUT PARAMETERS'!$C$29)^(K$16-1) -> 339652.48 | L18: =+$D$18*L17*(1+'SITE Model - INPUT PARAMETERS'!$C$29)^(L$16-1) -> 343049 | ... AB18: =+$D$18*AB17*(1+'SITE Model - INPUT PARAMETERS'!$C$29)^(AB$16-1) -> 402251.94
B19: Beverage | D19: =+D11*D17 -> 48000 | E19: =+$D$19*E17*(1+'SITE Model - INPUT PARAMETERS'!$C$29)^(E$16-1) -> 48480 | F19: =+$D$19*F17*(1+'SITE Model - INPUT PARAMETERS'!$C$29)^(F$16-1) -> 48964.8 | G19: =+$D$19*G17*(1+'SITE Model - INPUT PARAMETERS'!$C$29)^(G$16-1) -> 49454.448 | H19: =+$D$19*H17*(1+'SITE Model - INPUT PARAMETERS'!$C$29)^(H$16-1) -> 49948.992 | I19: =+$D$19*I17*(1+'SITE Model - INPUT PARAMETERS'!$C$29)^(I$16-1) -> 50448.482 | J19: =+$D$19*J17*(1+'SITE Model - INPUT PARAMETERS'!$C$29)^(J$16-1) -> 50952.967 | K19: =+$D$19*K17*(1+'SITE Model - INPUT PARAMETERS'!$C$29)^(K$16-1) -> 51462.497 | L19: =+$D$19*L17*(1+'SITE Model - INPUT PARAMETERS'!$C$29)^(L$16-1) -> 51977.122 | ... AB19: =+$D$19*AB17*(1+'SITE Model - INPUT PARAMETERS'!$C$29)^(AB$16-1) -> 60947.263
B20: Service charges | D20: =+E11*D17 -> 36480 | E20: =+$D$20*E17*(1+'SITE Model - INPUT PARAMETERS'!$C$29)^(E$16-1) -> 36844.8 | F20: =+$D$20*F17*(1+'SITE Model - INPUT PARAMETERS'!$C$29)^(F$16-1) -> 37213.248 | G20: =+$D$20*G17*(1+'SITE Model - INPUT PARAMETERS'!$C$29)^(G$16-1) -> 37585.38 | H20: =+$D$20*H17*(1+'SITE Model - INPUT PARAMETERS'!$C$29)^(H$16-1) -> 37961.234 | I20: =+$D$20*I17*(1+'SITE Model - INPUT PARAMETERS'!$C$29)^(I$16-1) -> 38340.847 | J20: =+$D$20*J17*(1+'SITE Model - INPUT PARAMETERS'!$C$29)^(J$16-1) -> 38724.255 | K20: =+$D$20*K17*(1+'SITE Model - INPUT PARAMETERS'!$C$29)^(K$16-1) -> 39111.498 | L20: =+$D$20*L17*(1+'SITE Model - INPUT PARAMETERS'!$C$29)^(L$16-1) -> 39502.613 | ... AB20: =+$D$20*AB17*(1+'SITE Model - INPUT PARAMETERS'!$C$29)^(AB$16-1) -> 46319.92
B21: Total Revenues | D21: =SUM(D18:D20) -> 401280 | E21: =SUM(E18:E20) -> 405292.8 | F21: =SUM(F18:F20) -> 409345.73 | G21: =SUM(G18:G20) -> 413439.19 | H21: =SUM(H18:H20) -> 417573.58 | I21: =SUM(I18:I20) -> 421749.31 | J21: =SUM(J18:J20) -> 425966.81 | K21: =SUM(K18:K20) -> 430226.47 | ... AB21: =SUM(AB18:AB20) -> 509519.12

Sheet Site Geneva revenues C
B2: PRODUCTION : based on assumptions
B4: Revenues C (BtB)
C5: Food | D5: Beverage | E5: Service Charges | F5: Total income
B6: percentage | C6: 0.7 | D6: 0.2 | E6: 0.1
B8: Monthly average | C8: =50*20*30 -> 30000 | D8: =25*20*10 -> 5000 | E8: =(C8+D8)*E6 -> 3500 | F8: =SUM(C8:E8) -> 38500
B11: yearly average value | C11: =C8*12 -> 360000 | D11: =D8*12 -> 60000 | E11: =E8*12 -> 42000 | F11: =+E11+D11+C11 -> 462000
B16: operating income (updated with inflaction) | D16: 1 | E16: =D16+1 -> 2 | F16: =E16+1 -> 3 | G16: =F16+1 -> 4 | H16: =G16+1 -> 5 | I16: =H16+1 -> 6 | J16: =I16+1 -> 7 | K16: =J16+1 -> 8 | L16: =K16+1 -> 9 | ... AB16: =AA16+1 -> 25
B17: implementation of the project | D17: 1 | E17: 1 | F17: 1 | G17: 1 | H17: 1 | I17: 1 | J17: 1 | K17: 1 | L17: 1 | M17: 1 | N17: 1 | O17: 1 | P17: 1 | Q17: 1 | R17: 1 | S17: 1 | T17: 1 | U17: 1 | V17: 1 | W17: 1 | X17: 1 | Y17: 1 | Z17: 1 | AA17: 1 | AB17: 1
B18: Food | D18: =+C11*D17 -> 360000 | E18: =+$D$18*E17*(1+'SITE Model - INPUT PARAMETERS'!$C$29)^(E$16-1) -> 363600 | F18: =+$D$18*F17*(1+'SITE Model - INPUT PARAMETERS'!$C$29)^(F$16-1) -> 367236 | G18: =+$D$18*G17*(1+'SITE Model - INPUT PARAMETERS'!$C$29)^(G$16-1) -> 370908.36 | H18: =+$D$18*H17*(1+'SITE Model - INPUT PARAMETERS'!$C$29)^(H$16-1) -> 374617.44 | I18: =+$D$18*I17*(1+'SITE Model - INPUT PARAMETERS'!$C$29)^(I$16-1) -> 378363.62 | J18: =+$D$18*J17*(1+'SITE Model - INPUT PARAMETERS'!$C$29)^(J$16-1) -> 382147.25 | K18: =+$D$18*K17*(1+'SITE Model - INPUT PARAMETERS'!$C$29)^(K$16-1) -> 385968.73 | L18: =+$D$18*L17*(1+'SITE Model - INPUT PARAMETERS'!$C$29)^(L$16-1) -> 389828.41 | ... AB18: =+$D$18*AB17*(1+'SITE Model - INPUT PARAMETERS'!$C$29)^(AB$16-1) -> 457104.47
B19: Beverage | D19: =+D11*D17 -> 60000 | E19: =+$D$19*E17*(1+'SITE Model - INPUT PARAMETERS'!$C$29)^(E$16-1) -> 60600 | F19: =+$D$19*F17*(1+'SITE Model - INPUT PARAMETERS'!$C$29)^(F$16-1) -> 61206 | G19: =+$D$19*G17*(1+'SITE Model - INPUT PARAMETERS'!$C$29)^(G$16-1) -> 61818.06 | H19: =+$D$19*H17*(1+'SITE Model - INPUT PARAMETERS'!$C$29)^(H$16-1) -> 62436.241 | I19: =+$D$19*I17*(1+'SITE Model - INPUT PARAMETERS'!$C$29)^(I$16-1) -> 63060.603 | J19: =+$D$19*J17*(1+'SITE Model - INPUT PARAMETERS'!$C$29)^(J$16-1) -> 63691.209 | K19: =+$D$19*K17*(1+'SITE Model - INPUT PARAMETERS'!$C$29)^(K$16-1) -> 64328.121 | L19: =+$D$19*L17*(1+'SITE Model - INPUT PARAMETERS'!$C$29)^(L$16-1) -> 64971.402 | ... AB19: =+$D$19*AB17*(1+'SITE Model - INPUT PARAMETERS'!$C$29)^(AB$16-1) -> 76184.079
B20: Service charges | D20: =+E11*D17 -> 42000 | E20: =+$D$20*E17*(1+'SITE Model - INPUT PARAMETERS'!$C$29)^(E$16-1) -> 42420 | F20: =+$D$20*F17*(1+'SITE Model - INPUT PARAMETERS'!$C$29)^(F$16-1) -> 42844.2 | G20: =+$D$20*G17*(1+'SITE Model - INPUT PARAMETERS'!$C$29)^(G$16-1) -> 43272.642 | H20: =+$D$20*H17*(1+'SITE Model - INPUT PARAMETERS'!$C$29)^(H$16-1) -> 43705.368 | I20: =+$D$20*I17*(1+'SITE Model - INPUT PARAMETERS'!$C$29)^(I$16-1) -> 44142.422 | J20: =+$D$20*J17*(1+'SITE Model - INPUT PARAMETERS'!$C$29)^(J$16-1) -> 44583.846 | K20: =+$D$20*K17*(1+'SITE Model - INPUT PARAMETERS'!$C$29)^(K$16-1) -> 45029.685 | L20: =+$D$20*L17*(1+'SITE Model - INPUT PARAMETERS'!$C$29)^(L$16-1) -> 45479.982 | ... AB20: =+$D$20*AB17*(1+'SITE Model - INPUT PARAMETERS'!$C$29)^(AB$16-1) -> 53328.855
B21: Total Revenues | D21: =SUM(D18:D20) -> 462000 | E21: =SUM(E18:E20) -> 466620 | F21: =SUM(F18:F20) -> 471286.2 | G21: =SUM(G18:G20) -> 475999.06 | H21: =SUM(H18:H20) -> 480759.05 | I21: =SUM(I18:I20) -> 485566.64 | J21: =SUM(J18:J20) -> 490422.31 | K21: =SUM(K18:K20) -> 495326.53 | ... AB21: =SUM(AB18:AB20) -> 586617.41

Sheet Site Zurich revenues A 
B2: PRODUCTION : based on assumptions
B4: Revenues A (Main)
C5: Food | D5: Beverage | E5: Service Charges | F5: Total income
B6: percentage | C6: 0.7 | D6: 0.2 | E6: 0.1
B8: Monthly average | C8: =80*22*40 -> 70400 | D8: =40*22*10 -> 8800 | E8: =(C8+D8)*E6 -> 7920 | F8: =SUM(C8:E8) -> 87120
B11: yearly average value | C11: =C8*12 -> 844800 | D11: =D8*12 -> 105600 | E11: =E8*12 -> 95040 | F11: =+E11+D11+C11 -> 1045440
B16: operating income (updated with inflaction) | D16: 1 | E16: =D16+1 -> 2 | F16: =E16+1 -> 3 | G16: =F16+1 -> 4 | H16: =G16+1 -> 5 | I16: =H16+1 -> 6 | J16: =I16+1 -> 7 | K16: =J16+1 -> 8 | L16: =K16+1 -> 9 | ... AB16: =AA16+1 -> 25
B17: implementation of the project | E17: 1 | F17: 1 | G17: 1 | H17: 1 | I17: 1 | J17: 1 | K17: 1 | L17: 1 | M17: 1 | N17: 1 | O17: 1 | P17: 1 | Q17: 1 | R17: 1 | S17: 1 | T17: 1 | U17: 1 | V17: 1 | W17: 1 | X17: 1 | Y17: 1 | Z17: 1 | AA17: 1 | AB17: 1 | AC17: 1
B18: Food | E18: =+C11*E17 -> 844800 | F18: =+$E$18*F17*(1+'SITE Model - INPUT PARAMETERS'!$C$29)^(E$16-1) -> 853248 | G18: =+$E$18*G17*(1+'SITE Model - INPUT PARAMETERS'!$C$29)^(F$16-1) -> 861780.48 | H18: =+$E$18*H17*(1+'SITE Model - INPUT PARAMETERS'!$C$29)^(G$16-1) -> 870398.28 | I18: =+$E$18*I17*(1+'SITE Model - INPUT PARAMETERS'!$C$29)^(H$16-1) -> 879102.27 | J18: =+$E$18*J17*(1+'SITE Model - INPUT PARAMETERS'!$C$29)^(I$16-1) -> 887893.29 | K18: =+$E$18*K17*(1+'SITE Model - INPUT PARAMETERS'!$C$29)^(J$16-1) -> 896772.22 | L18: =+$E$18*L17*(1+'SITE Model - INPUT PARAMETERS'!$C$29)^(K$16-1) -> 905739.95 | M18: =+$E$18*M17*(1+'SITE Model - INPUT PARAMETERS'!$C$29)^(L$16-1) -> 914797.34 | ... AC18: =+$E$18*AC17*(1+'SITE Model - INPUT PARAMETERS'!$C$29)^(AB$16-1) -> 1072671.8
B19: Beverage | E19: =+D11*E17 -> 105600 | F19: =+$E$19*F17*(1+'SITE Model - INPUT PARAMETERS'!$C$29)^(E$16-1) -> 106656 | G19: =+$E$19*G17*(1+'SITE Model - INPUT PARAMETERS'!$C$29)^(F$16-1) -> 107722.56 | H19: =+$E$19*H17*(1+'SITE Model - INPUT PARAMETERS'!$C$29)^(G$16-1) -> 108799.79 | I19: =+$E$19*I17*(1+'SITE Model - INPUT PARAMETERS'!$C$29)^(H$16-1) -> 109887.78 | J19: =+$E$19*J17*(1+'SITE Model - INPUT PARAMETERS'!$C$29)^(I$16-1) -> 110986.66 | K19: =+$E$19*K17*(1+'SITE Model - INPUT PARAMETERS'!$C$29)^(J$16-1) -> 112096.53 | L19: =+$E$19*L17*(1+'SITE Model - INPUT PARAMETERS'!$C$29)^(K$16-1) -> 113217.49 | M19: =+$E$19*M17*(1+'SITE Model - INPUT PARAMETERS'!$C$29)^(L$16-1) -> 114349.67 | ... AC19: =+$E$19*AC17*(1+'SITE Model - INPUT PARAMETERS'!$C$29)^(AB$16-1) -> 134083.98
B20: Service charges | E20: =+E11*E17 -> 95040 | F20: =+$E$20*F17*(1+'SITE Model - INPUT PARAMETERS'!$C$29)^(E$16-1) -> 95990.4 | G20: =+$E$20*G17*(1+'SITE Model - INPUT PARAMETERS'!$C$29)^(F$16-1) -> 96950.304 | H20: =+$E$20*H17*(1+'SITE Model - INPUT PARAMETERS'!$C$29)^(G$16-1) -> 97919.807 | I20: =+$E$20*I17*(1+'SITE Model - INPUT PARAMETERS'!$C$29)^(H$16-1) -> 98899.005 | J20: =+$E$20*J17*(1+'SITE Model - INPUT PARAMETERS'!$C$29)^(I$16-1) -> 99887.995 | K20: =+$E$20*K17*(1+'SITE Model - INPUT PARAMETERS'!$C$29)^(J$16-1) -> 100886.88 | L20: =+$E$20*L17*(1+'SITE Model - INPUT PARAMETERS'!$C$29)^(K$16-1) -> 101895.74 | M20: =+$E$20*M17*(1+'SITE Model - INPUT PARAMETERS'!$C$29)^(L$16-1) -> 102914.7 | ... AC20: =+$E$20*AC17*(1+'SITE Model - INPUT PARAMETERS'!$C$29)^(AB$16-1) -> 120675.58
B21: Total Revenues | E21: =SUM(E18:E20) -> 1045440 | F21: =SUM(F18:F20) -> 1055894.4 | G21: =SUM(G18:G20) -> 1066453.3 | H21: =SUM(H18:H20) -> 1077117.9 | I21: =SUM(I18:I20) -> 1087889.1 | J21: =SUM(J18:J20) -> 1098767.9 | K21: =SUM(K18:K20) -> 1109755.6 | L21: =SUM(L18:L20) -> 1120853.2 | ... AC21: =SUM(AC18:AC20) -> 1327431.4

Sheet Site Zurch revenues B 
B2: PRODUCTION : based on assumptions
B4: Revenues B (HD)
C5: Food | D5: Beverage | E5: Service Charges | F5: Total income
B6: percentage | C6: 0.7 | D6: 0.2 | E6: 0.1
B8: Monthly average | C8: =40*22*30 -> 26400 | D8: =20*20*10 -> 4000 | E8: =(C8+D8)*E6 -> 3040 | F8: =SUM(C8:E8) -> 33440
B11: yearly average value | C11: =C8*12 -> 316800 | D11: =D8*12 -> 48000 | E11: =E8*12 -> 36480 | F11: =+E11+D11+C11 -> 401280
B16: operating income (updated with inflaction) | D16: 1 | E16: =D16+1 -> 2 | F16: =E16+1 -> 3 | G16: =F16+1 -> 4 | H16: =G16+1 -> 5 | I16: =H16+1 -> 6 | J16: =I16+1 -> 7 | K16: =J16+1 -> 8 | L16: =K16+1 -> 9 | ... AB16: =AA16+1 -> 25
B17: implementation of the project | E17: 1 | F17: 1 | G17: 1 | H17: 1 | I17: 1 | J17: 1 | K17: 1 | L17: 1 | M17: 1 | N17: 1 | O17: 1 | P17: 1 | Q17: 1 | R17: 1 | S17: 1 | T17: 1 | U17: 1 | V17: 1 | W17: 1 | X17: 1 | Y17: 1 | Z17: 1 | AA17: 1 | AB17: 1 | AC17: 1
B18: Food | E18: =+C11*E17 -> 316800 | F18: =+$E$18*F17*(1+'SITE Model - INPUT PARAMETERS'!$C$29)^(E$16-1) -> 319968 | G18: =+$E$18*G17*(1+'SITE Model - INPUT PARAMETERS'!$C$29)^(F$16-1) -> 323167.68 | H18: =+$E$18*H17*(1+'SITE Model - INPUT PARAMETERS'!$C$29)^(G$16-1) -> 326399.36 | I18: =+$E$18*I17*(1+'SITE Model - INPUT PARAMETERS'!$C$29)^(H$16-1) -> 329663.35 | J18: =+$E$18*J17*(1+'SITE Model - INPUT PARAMETERS'!$C$29)^(I$16-1) -> 332959.98 | K18: =+$E$18*K17*(1+'SITE Model - INPUT PARAMETERS'!$C$29)^(J$16-1) -> 336289.58 | L18: =+$E$18*L17*(1+'SITE Model - INPUT PARAMETERS'!$C$29)^(K$16-1) -> 339652.48 | M18: =+$E$18*M17*(1+'SITE Model - INPUT PARAMETERS'!$C$29)^(L$16-1) -> 343049 | ... AC18: =+$E$18*AC17*(1+'SITE Model - INPUT PARAMETERS'!$C$29)^(AB$16-1) -> 402251.94
B19: Beverage | E19: =+D11*E17 -> 48000 | F19: =+$E$19*F17*(1+'SITE Model - INPUT PARAMETERS'!$C$29)^(E$16-1) -> 48480 | G19: =+$E$19*G17*(1+'SITE Model - INPUT PARAMETERS'!$C$29)^(F$16-1) -> 48964.8 | H19: =+$E$19*H17*(1+'SITE Model - INPUT PARAMETERS'!$C$29)^(G$16-1) -> 49454.448 | I19: =+$E$19*I17*(1+'SITE Model - INPUT PARAMETERS'!$C$29)^(H$16-1) -> 49948.992 | J19: =+$E$19*J17*(1+'SITE Model - INPUT PARAMETERS'!$C$29)^(I$16-1) -> 50448.482 | K19: =+$E$19*K17*(1+'SITE Model - INPUT PARAMETERS'!$C$29)^(J$16-1) -> 50952.967 | L19: =+$E$19*L17*(1+'SITE Model - INPUT PARAMETERS'!$C$29)^(K$16-1) -> 51462.497 | M19: =+$E$19*M17*(1+'SITE Model - INPUT PARAMETERS'!$C$29)^(L$16-1) -> 51977.122 | ... AC19: =+$E$19*AC17*(1+'SITE Model - INPUT PARAMETERS'!$C$29)^(AB$16-1) -> 60947.263
